Workbook

Sheet 개요
A1: 시스템 | B1: DB 계정
A2: ISM | B2: ISM_2603
A3: SIP | B3: SIPMES_260223

Sheet 1. Tables
A1: 테이블 존재 | B1: Table Name | C1: Description | D1: Curr / Hist | E1: TableSpace for Table | F1: TableSpace for Index | G1: Table Partition
A2: SIP | B2: ALARM | D2: Master | E2: SIPMES | F2: USERS
A3: SIP | B3: ALARMACTION | D3: Master | E3: SIPMES | F3: USERS
A4: SIP | B4: ALARMACTIONHISTORY | D4: Master | E4: SIPMES | F4: USERS
A5: SIP | B5: ALARMCODE | D5: Master | E5: USERS | F5: USERS
A6: SIP | B6: ALARMCODEHISTORY | D6: Master | E6: SIPMES
A7: SIP | B7: ALARMGROUP | D7: Master | E7: SIPMES | F7: USERS
A8: SIP | B8: ALARMGROUPHISTORY | D8: Master | E8: SIPMES | F8: USERS
A9: SIP | B9: ALARMHISTORY | D9: Master | E9: SIPMES | F9: USERS
A10: SIP | B10: ALARMSCOPE | D10: Master | E10: SIPMES | F10: USERS
A11: SIP | B11: ALARMSCOPEHISTORY | D11: Master | E11: SIPMES | F11: USERS
A12: ALL | B12: AREA | C12: 생산 영역 기준정보 | D12: Master | E12: GC_MES_MDM_DAT | F12: GC_MES_MDM_IDX
A13: ALL | B13: AREAHISTORY | C13: 생산 영역 기준정보 이력 | D13: History | E13: GC_MES_HIST_DAT | F13: GC_MES_HIST_IDX
A14: ALL | B14: ATTRIBUTE | C14: 기준정보 공통UI 그리드항목 모델링 기준정보 | D14: Master | E14: GC_MES_MDM_DAT | F14: GC_MES_MDM_IDX
A15: ALL | B15: ATTRIBUTEHISTORY | C15: 기준정보 공통UI 그리드항목 모델링 기준정보 | D15: History | E15: GC_MES_HIST_DAT | F15: GC_MES_HIST_IDX
A16: ALL | B16: AUTHOR | C16: 권한ID 기준정보 | D16: Master | E16: GC_MES_MDM_DAT | F16: GC_MES_MDM_IDX
A17: ALL | B17: AUTHORHISTORY | C17: 권한그룹ID 기준정보 | D17: History | E17: GC_MES_HIST_DAT | F17: GC_MES_HIST_IDX
A18: ALL | B18: AUTHORMENU | C18: 권한그룹별 메뉴권한 매핑정보 | D18: Master | E18: GC_MES_MDM_DAT | F18: GC_MES_MDM_IDX
A19: ALL | B19: AUTHORMENUHISTORY | C19: 권한그룹별 메뉴권한 매핑정보 | D19: History | E19: GC_MES_HIST_DAT | F19: GC_MES_HIST_IDX
A20: ALL | B20: AUTHREASONCODE | C20: 권한별 사유코드 관리 | D20: Master | E20: GC_MES_MDM_DAT | F20: GC_MES_MDM_IDX
A21: ALL | B21: AUTHREASONCODEHISTORY | D21: Master | E21: GC_MES_MDM_DAT | F21: GC_MES_HIST_IDX
A22: ALL | B22: BEHAVIOR | C22: 기준정보 공통UI 그리드항목 모델링 기준정보 | D22: Master | E22: GC_MES_MDM_DAT | F22: GC_MES_MDM_IDX
A23: ALL | B23: BEHAVIORHISTORY | C23: 기준정보 공통UI 그리드항목 모델링 기준정보 | D23: History | E23: GC_MES_HIST_DAT | F23: GC_MES_HIST_IDX
A24: ALL | B24: CARRIER | C24: 캐리어 ID 정보 | D24: Master | E24: GC_MES_STD_DAT | F24: GC_MES_STD_IDX
A25: ALL | B25: CARRIERDEF | C25: 캐리어 기준정보 | D25: Master | E25: GC_MES_MDM_DAT | F25: GC_MES_MDM_IDX
A26: ALL | B26: CARRIERDEFHISTORY | C26: 캐리어 기준정보 이력 | D26: History | E26: GC_MES_HIST_DAT | F26: GC_MES_HIST_IDX
A27: ALL | B27: CARRIERHISTORY | C27: 캐리어 기준정보 이력 | D27: History | E27: GC_MES_HIST_DAT | F27: GC_MES_HIST_IDX
A28: SIP | B28: CHECKINLINE | C28: ^Available^STND^RT^RESOURCE^Current^^Off^ACM | D28: Master | E28: GC_MES_MDM_DAT | F28: GC_MES_MDM_DAT
A29: SIP | B29: CHECKINLINEHISTORY | D29: Master | E29: GC_MES_MDM_DAT | F29: GC_MES_MDM_DAT
A30: SIP | B30: CLIENT | D30: Master | E30: USERS | F30: USERS
A31: SIP | B31: CLIENT_LOG | C31: 클라이언트 로그 저장 테이블 | D31: Master | E31: SIPMES_251229 | F31: SIPMES_251229
A32: SIP | B32: CLIENTHISTORY | D32: Master | E32: USERS | F32: USERS
A33: ALL | B33: COLUMNDEF | D33: Master | E33: GC_MES_MDM_DAT
A34: ISM | B34: CONSTANTDEF | C34: 상수 정의 기준정보 | D34: Master | E34: GC_MES_MDM_DAT | F34: GC_MES_MDM_IDX
A35: ISM | B35: CONSTANTDEFHISTORY | C35: 상수 정의 기준정보 | D35: History | E35: GC_MES_HIST_DAT | F35: GC_MES_HIST_IDX
A36: ALL | B36: CONSUMABLELOT | C36: 소모성자재LOT 정보 | D36: Master | E36: GC_MES_STD_DAT | F36: GC_MES_STD_IDX
A37: ALL | B37: CONSUMABLELOTHISTORY | C37: 소모성자재LOT 정보 | D37: History | E37: GC_MES_HIST_DAT | F37: GC_MES_HIST_IDX
A38: SIP | B38: DEFECTSUMMARY | D38: Master | E38: USERS | F38: USERS
A39: SIP | B39: DEFECTSUMMARYHISTORY | D39: Master | E39: USERS | F39: USERS
A40: SIP | B40: DEFECTYIELDHISTORY | D40: Master | E40: USERS | F40: USERS
...

Sheet 2. Columns
A1: 분석 | B1: 테이블 존재 | C1: 컬럼 존재 | D1: 적용방법 | E1: Table Name | F1: Column Name | G1: Column ID | H1: Type | I1: Length | J1: Null 허용 | K1: PK | L1: Description
A2: 테이블이 SIP에만 존재 | B2: SIP | C2: SIP | E2: ALARM | F2: ALARMID | G2: 1 | H2: VARCHAR2 | I2: 40 | J2: N | K2: PK | L2: 발생한 ALARM별 Unique한 ID
A3: 테이블이 SIP에만 존재 | B3: SIP | C3: SIP | E3: ALARM | F3: FACTORYID | G3: 2 | H3: VARCHAR2 | I3: 40 | J3: N | K3: PK | L3: 공장 ID
A4: 테이블이 SIP에만 존재 | B4: SIP | C4: SIP | E4: ALARM | F4: ALARMGROUPID | G4: 3 | H4: VARCHAR2 | I4: 40 | J4: Y | L4: ALARM을 발생시키는 곳 (EQP, SPC, SYSTEM)
A5: 테이블이 SIP에만 존재 | B5: SIP | C5: SIP | E5: ALARM | F5: ALARMLEVEL | G5: 4 | H5: VARCHAR2 | I5: 40 | J5: Y | L5: ALARM 등급에 대한 Level(INFO, WARNING, ALARM)
A6: 테이블이 SIP에만 존재 | B6: SIP | C6: SIP | E6: ALARM | F6: ALARMCODE | G6: 5 | H6: VARCHAR2 | I6: 40 | J6: Y | L6: ALARM이 발생될때 장비등에서 부여하는 Code
A7: 테이블이 SIP에만 존재 | B7: SIP | C7: SIP | E7: ALARM | F7: ALARMTYPE | G7: 6 | H7: VARCHAR2 | I7: 40 | J7: Y | L7: ALARM 발생후 사용자가 발생한 Alarm을 handling할수 있는 범위들의 Type(ACTIVATE, ACKNOWLEDGE, CLEAR)
A8: 테이블이 SIP에만 존재 | B8: SIP | C8: SIP | E8: ALARM | F8: DESTTYPE | G8: 7 | H8: VARCHAR2 | I8: 40 | J8: Y | L8: ALARM 발생시 발생한 ALARM을 알릴수 있는 범위(FAB, Area, Equipment)
A9: 테이블이 SIP에만 존재 | B9: SIP | C9: SIP | E9: ALARM | F9: ALARMTEXT | G9: 8 | H9: VARCHAR2 | I9: 1000 | J9: Y | L9: 발생한 ALARM에 대한 상세 내용
A10: 테이블이 SIP에만 존재 | B10: SIP | C10: SIP | E10: ALARM | F10: ALARMSOLVE | G10: 9 | H10: VARCHAR2 | I10: 400 | J10: Y | L10: ALARM 대응방안
A11: 테이블이 SIP에만 존재 | B11: SIP | C11: SIP | E11: ALARM | F11: ALARMSTATE | G11: 10 | H11: VARCHAR2 | I11: 40 | J11: Y | L11: 발생한 ALARM의 State (ACTIVATED/ACKNOWLEDGED/CLEARED)
A12: 테이블이 SIP에만 존재 | B12: SIP | C12: SIP | E12: ALARM | F12: AREAID | G12: 11 | H12: VARCHAR2 | I12: 40 | J12: Y | L12: ALARM이 발생한 AREAID
A13: 테이블이 SIP에만 존재 | B13: SIP | C13: SIP | E13: ALARM | F13: EQUIPMENTID | G13: 12 | H13: VARCHAR2 | I13: 40 | J13: Y | L13: ALARM이 발생된 설비에 부여된 고유한 이름
A14: 테이블이 SIP에만 존재 | B14: SIP | C14: SIP | E14: ALARM | F14: ACKTIME | G14: 13 | H14: DATE | I14: 7 | J14: Y | L14: ALARM State가 Acknowledge일때 시간
A15: 테이블이 SIP에만 존재 | B15: SIP | C15: SIP | E15: ALARM | F15: ACKUSER | G15: 14 | H15: VARCHAR2 | I15: 40 | J15: Y | L15: ALARM State가 Acknowledge로 변경한 User
... A27: 테이블이 SIP에만 존재 | B27: SIP | C27: SIP | E27: ALARM | F27: EVENTCOMMENT | G27: 26 | H27: VARCHAR2 | I27: 500 | J27: Y | L27: System 커맨트
A28: 테이블이 SIP에만 존재 | B28: SIP | C28: SIP | E28: ALARMACTION | F28: ALARMGROUPID | G28: 1 | H28: VARCHAR2 | I28: 40 | J28: N | K28: PK | L28: ALARM을 발생시키는 곳 (EQP, SPC, SYSTEM)
A29: 테이블이 SIP에만 존재 | B29: SIP | C29: SIP | E29: ALARMACTION | F29: FACTORYID | G29: 2 | H29: VARCHAR2 | I29: 40 | J29: N | K29: PK | L29: 공장 ID
A30: 테이블이 SIP에만 존재 | B30: SIP | C30: SIP | E30: ALARMACTION | F30: ALARMLEVEL | G30: 3 | H30: VARCHAR2 | I30: 40 | J30: N | K30: PK | L30: ALARM 등급에 대한 Level(INFO, WARNING, ALARM)
A31: 테이블이 SIP에만 존재 | B31: SIP | C31: SIP | E31: ALARMACTION | F31: ALARMTYPE | G31: 4 | H31: VARCHAR2 | I31: 40 | J31: N | K31: PK | L31: ALARM 발생후 사용자가 발생한 Alarm을 handling할수 있는 범위들의 Type(ACTIVATE, ACKNOWLEDGE, CLEAR)
A32: 테이블이 SIP에만 존재 | B32: SIP | C32: SIP | E32: ALARMACTION | F32: ACTION | G32: 5 | H32: VARCHAR2 | I32: 40 | J32: N | K32: PK | L32: ALARM 발생시 알람행위(HoldLot,HoldEQP,Email,SMS,AlarmLamp)
A33: 테이블이 SIP에만 존재 | B33: SIP | C33: SIP | E33: ALARMACTION | F33: CHECKOUTSTATE | G33: 6 | H33: VARCHAR2 | I33: 40 | J33: Y | L33: User별 데이터 편집상태 (CheckedIn/CheckedOut/CancelCheckedOut)
A34: 테이블이 SIP에만 존재 | B34: SIP | C34: SIP | E34: ALARMACTION | F34: CHECKOUTTIME | G34: 7 | H34: DATE | I34: 7 | J34: Y | L34: 데이터 편집위해 CheckOut시간
A35: 테이블이 SIP에만 존재 | B35: SIP | C35: SIP | E35: ALARMACTION | F35: CHECKOUTUSER | G35: 8 | H35: VARCHAR2 | I35: 40 | J35: Y | L35: CheckOut 사용자ID
A36: 테이블이 SIP에만 존재 | B36: SIP | C36: SIP | E36: ALARMACTION | F36: DATASTATE | G36: 9 | H36: VARCHAR2 | I36: 10 | J36: Y | L36: 변경 상태 (Created/Removed)
A37: 테이블이 SIP에만 존재 | B37: SIP | C37: SIP | E37: ALARMACTION | F37: EVENT | G37: 10 | H37: VARCHAR2 | I37: 40 | J37: Y | L37: 이벤트 (CheckedIn/CheckedOut/CancelCheckedOut/Created/Modify/Removed)
A38: 테이블이 SIP에만 존재 | B38: SIP | C38: SIP | E38: ALARMACTION | F38: TIMEKEY | G38: 11 | H38: VARCHAR2 | I38: 40 | J38: Y | L38: 이벤트 발생 Key
A39: 테이블이 SIP에만 존재 | B39: SIP | C39: SIP | E39: ALARMACTION | F39: EVENTTIME | G39: 12 | H39: DATE | I39: 7 | J39: Y | L39: 이벤트 발생 시간
A40: 테이블이 SIP에만 존재 | B40: SIP | C40: SIP | E40: ALARMACTION | F40: EVENTUSER | G40: 13 | H40: VARCHAR2 | I40: 40 | J40: Y | L40: 이벤트 발생 사용자
A41: 테이블이 SIP에만 존재 | B41: SIP | C41: SIP | E41: ALARMACTION | F41: EVENTCOMMENT | G41: 14 | H41: VARCHAR2 | I41: 500 | J41: Y | L41: System 커맨트
A42: 테이블이 SIP에만 존재 | B42: SIP | C42: SIP | E42: ALARMACTIONHISTORY | F42: ALARMGROUPID | G42: 1 | H42: VARCHAR2 | I42: 40 | J42: N | K42: PK | L42: ALARM을 발생시키는 곳 (EQP, SPC, SYSTEM)
A43: 테이블이 SIP에만 존재 | B43: SIP | C43: SIP | E43: ALARMACTIONHISTORY | F43: FACTORYID | G43: 2 | H43: VARCHAR2 | I43: 40 | J43: N | K43: PK | L43: 공장 ID
A44: 테이블이 SIP에만 존재 | B44: SIP | C44: SIP | E44: ALARMACTIONHISTORY | F44: ALARMLEVEL | G44: 3 | H44: VARCHAR2 | I44: 40 | J44: N | K44: PK | L44: ALARM 등급에 대한 Level(INFO, WARNING, ALARM)
A45: 테이블이 SIP에만 존재 | B45: SIP | C45: SIP | E45: ALARMACTIONHISTORY | F45: ALARMTYPE | G45: 4 | H45: VARCHAR2 | I45: 40 | J45: N | K45: PK | L45: ALARM 발생후 사용자가 발생한 Alarm을 handling할수 있는 범위들의 Type(ACTIVATE, ACKNOWLEDGE, CLEAR)
A46: 테이블이 SIP에만 존재 | B46: SIP | C46: SIP | E46: ALARMACTIONHISTORY | F46: ACTION | G46: 5 | H46: VARCHAR2 | I46: 40 | J46: N | K46: PK | L46: ALARM 발생시 알람행위(HoldLot,HoldEQP,Email,SMS,AlarmLamp)
A47: 테이블이 SIP에만 존재 | B47: SIP | C47: SIP | E47: ALARMACTIONHISTORY | F47: CHECKOUTSTATE | G47: 6 | H47: VARCHAR2 | I47: 40 | J47: Y | L47: User별 데이터 편집상태 (CheckedIn/CheckedOut/CancelCheckedOut)
A48: 테이블이 SIP에만 존재 | B48: SIP | C48: SIP | E48: ALARMACTIONHISTORY | F48: CHECKOUTTIME | G48: 7 | H48: DATE | I48: 7 | J48: Y | L48: 데이터 편집위해 CheckOut시간
A49: 테이블이 SIP에만 존재 | B49: SIP | C49: SIP | E49: ALARMACTIONHISTORY | F49: CHECKOUTUSER | G49: 8 | H49: VARCHAR2 | I49: 40 | J49: Y | L49: CheckOut 사용자ID
A50: 테이블이 SIP에만 존재 | B50: SIP | C50: SIP | E50: ALARMACTIONHISTORY | F50: DATASTATE | G50: 9 | H50: VARCHAR2 | I50: 10 | J50: Y | L50: 변경 상태 (Created/Removed)
A51: 테이블이 SIP에만 존재 | B51: SIP | C51: SIP | E51: ALARMACTIONHISTORY | F51: EVENT | G51: 10 | H51: VARCHAR2 | I51: 40 | J51: Y | L51: 이벤트 (CheckedIn/CheckedOut/CancelCheckedOut/Created/Modify/Removed)
...

Sheet 테이블_ISM
A1: 테이블 존재 | B1: TABLE_NAME | C1: COMMENTS | D1: CURHIST | E1: TABLESPACE_TABLE | F1: TABLESPACE_INDEX | G1: PARTITION_BY
A2: =IF(COUNTIFS(테이블_SIP!$B$2:$B$214, 테이블_ISM!B2)=0, "ISM", "ALL") -> ALL | B2: AREA | C2: 생산 영역 기준정보 | D2: Master | E2: GC_MES_MDM_DAT | F2: GC_MES_MDM_IDX
A3: =IF(COUNTIFS(테이블_SIP!$B$2:$B$214, 테이블_ISM!B3)=0, "ISM", "ALL") -> ALL | B3: AREAHISTORY | C3: 생산 영역 기준정보 이력 | D3: History | E3: GC_MES_HIST_DAT | F3: GC_MES_HIST_IDX
A4: =IF(COUNTIFS(테이블_SIP!$B$2:$B$214, 테이블_ISM!B4)=0, "ISM", "ALL") -> ALL | B4: ATTRIBUTE | C4: 기준정보 공통UI 그리드항목 모델링 기준정보 | D4: Master | E4: GC_MES_MDM_DAT | F4: GC_MES_MDM_IDX
A5: =IF(COUNTIFS(테이블_SIP!$B$2:$B$214, 테이블_ISM!B5)=0, "ISM", "ALL") -> ALL | B5: ATTRIBUTEHISTORY | C5: 기준정보 공통UI 그리드항목 모델링 기준정보 | D5: History | E5: GC_MES_HIST_DAT | F5: GC_MES_HIST_IDX
A6: =IF(COUNTIFS(테이블_SIP!$B$2:$B$214, 테이블_ISM!B6)=0, "ISM", "ALL") -> ALL | B6: AUTHOR | C6: 권한ID 기준정보 | D6: Master | E6: GC_MES_MDM_DAT | F6: GC_MES_MDM_IDX
A7: =IF(COUNTIFS(테이블_SIP!$B$2:$B$214, 테이블_ISM!B7)=0, "ISM", "ALL") -> ALL | B7: AUTHORHISTORY | C7: 권한그룹ID 기준정보 | D7: History | E7: GC_MES_HIST_DAT | F7: GC_MES_HIST_IDX
A8: =IF(COUNTIFS(테이블_SIP!$B$2:$B$214, 테이블_ISM!B8)=0, "ISM", "ALL") -> ALL | B8: AUTHORMENU | C8: 권한그룹별 메뉴권한 매핑정보 | D8: Master | E8: GC_MES_MDM_DAT | F8: GC_MES_MDM_IDX
A9: =IF(COUNTIFS(테이블_SIP!$B$2:$B$214, 테이블_ISM!B9)=0, "ISM", "ALL") -> ALL | B9: AUTHORMENUHISTORY | C9: 권한그룹별 메뉴권한 매핑정보 | D9: History | E9: GC_MES_HIST_DAT | F9: GC_MES_HIST_IDX
A10: =IF(COUNTIFS(테이블_SIP!$B$2:$B$214, 테이블_ISM!B10)=0, "ISM", "ALL") -> ALL | B10: AUTHREASONCODE | C10: 권한별 사유코드 관리 | D10: Master | E10: GC_MES_MDM_DAT | F10: GC_MES_MDM_IDX
A11: =IF(COUNTIFS(테이블_SIP!$B$2:$B$214, 테이블_ISM!B11)=0, "ISM", "ALL") -> ALL | B11: AUTHREASONCODEHISTORY | D11: Master | E11: GC_MES_MDM_DAT | F11: GC_MES_HIST_IDX
A12: =IF(COUNTIFS(테이블_SIP!$B$2:$B$214, 테이블_ISM!B12)=0, "ISM", "ALL") -> ALL | B12: BEHAVIOR | C12: 기준정보 공통UI 그리드항목 모델링 기준정보 | D12: Master | E12: GC_MES_MDM_DAT | F12: GC_MES_MDM_IDX
A13: =IF(COUNTIFS(테이블_SIP!$B$2:$B$214, 테이블_ISM!B13)=0, "ISM", "ALL") -> ALL | B13: BEHAVIORHISTORY | C13: 기준정보 공통UI 그리드항목 모델링 기준정보 | D13: History | E13: GC_MES_HIST_DAT | F13: GC_MES_HIST_IDX
A14: =IF(COUNTIFS(테이블_SIP!$B$2:$B$214, 테이블_ISM!B14)=0, "ISM", "ALL") -> ALL | B14: CARRIER | C14: 캐리어 ID 정보 | D14: Master | E14: GC_MES_STD_DAT | F14: GC_MES_STD_IDX
A15: =IF(COUNTIFS(테이블_SIP!$B$2:$B$214, 테이블_ISM!B15)=0, "ISM", "ALL") -> ALL | B15: CARRIERDEF | C15: 캐리어 기준정보 | D15: Master | E15: GC_MES_MDM_DAT | F15: GC_MES_MDM_IDX
A16: =IF(COUNTIFS(테이블_SIP!$B$2:$B$214, 테이블_ISM!B16)=0, "ISM", "ALL") -> ALL | B16: CARRIERDEFHISTORY | C16: 캐리어 기준정보 이력 | D16: History | E16: GC_MES_HIST_DAT | F16: GC_MES_HIST_IDX
A17: =IF(COUNTIFS(테이블_SIP!$B$2:$B$214, 테이블_ISM!B17)=0, "ISM", "ALL") -> ALL | B17: CARRIERHISTORY | C17: 캐리어 기준정보 이력 | D17: History | E17: GC_MES_HIST_DAT | F17: GC_MES_HIST_IDX
A18: =IF(COUNTIFS(테이블_SIP!$B$2:$B$214, 테이블_ISM!B18)=0, "ISM", "ALL") -> ALL | B18: COLUMNDEF | D18: Master | E18: GC_MES_MDM_DAT
A19: =IF(COUNTIFS(테이블_SIP!$B$2:$B$214, 테이블_ISM!B19)=0, "ISM", "ALL") -> ISM | B19: CONSTANTDEF | C19: 상수 정의 기준정보 | D19: Master | E19: GC_MES_MDM_DAT | F19: GC_MES_MDM_IDX
A20: =IF(COUNTIFS(테이블_SIP!$B$2:$B$214, 테이블_ISM!B20)=0, "ISM", "ALL") -> ISM | B20: CONSTANTDEFHISTORY | C20: 상수 정의 기준정보 | D20: History | E20: GC_MES_HIST_DAT | F20: GC_MES_HIST_IDX
A21: =IF(COUNTIFS(테이블_SIP!$B$2:$B$214, 테이블_ISM!B21)=0, "ISM", "ALL") -> ALL | B21: CONSUMABLELOT | C21: 소모성자재LOT 정보 | D21: Master | E21: GC_MES_STD_DAT | F21: GC_MES_STD_IDX
A22: =IF(COUNTIFS(테이블_SIP!$B$2:$B$214, 테이블_ISM!B22)=0, "ISM", "ALL") -> ALL | B22: CONSUMABLELOTHISTORY | C22: 소모성자재LOT 정보 | D22: History | E22: GC_MES_HIST_DAT | F22: GC_MES_HIST_IDX
A23: =IF(COUNTIFS(테이블_SIP!$B$2:$B$214, 테이블_ISM!B23)=0, "ISM", "ALL") -> ALL | B23: DURABLELOT | C23: Durable자재 LOT 정보 | D23: Master | E23: GC_MES_STD_DAT | F23: GC_MES_STD_IDX
A24: =IF(COUNTIFS(테이블_SIP!$B$2:$B$214, 테이블_ISM!B24)=0, "ISM", "ALL") -> ALL | B24: DURABLELOTHISTORY | C24: Durable자재LOT 정보 이력 | D24: History | E24: GC_MES_HIST_DAT
A25: =IF(COUNTIFS(테이블_SIP!$B$2:$B$214, 테이블_ISM!B25)=0, "ISM", "ALL") -> ISM | B25: EAPERRORLOG | D25: Master | E25: DXPLUS
A26: =IF(COUNTIFS(테이블_SIP!$B$2:$B$214, 테이블_ISM!B26)=0, "ISM", "ALL") -> ALL | B26: ENUM | C26: 기타코드 정의 | D26: Master | E26: GC_MES_MDM_DAT | F26: GC_MES_MDM_IDX
A27: =IF(COUNTIFS(테이블_SIP!$B$2:$B$214, 테이블_ISM!B27)=0, "ISM", "ALL") -> ALL | B27: ENUMHISTORY | C27: 기타코드 정의 | D27: History | E27: GC_MES_HIST_DAT | F27: GC_MES_HIST_IDX
A28: =IF(COUNTIFS(테이블_SIP!$B$2:$B$214, 테이블_ISM!B28)=0, "ISM", "ALL") -> ALL | B28: ENUMVALUE | C28: 기타코드의 Enum 코드정의 기준정보 | D28: Master | E28: GC_MES_MDM_DAT | F28: GC_MES_MDM_IDX
A29: =IF(COUNTIFS(테이블_SIP!$B$2:$B$214, 테이블_ISM!B29)=0, "ISM", "ALL") -> ALL | B29: ENUMVALUEHISTORY | C29: 기타코드의 Enum 코드정의 기준정보 | D29: History | E29: GC_MES_HIST_DAT | F29: GC_MES_HIST_IDX
A30: =IF(COUNTIFS(테이블_SIP!$B$2:$B$214, 테이블_ISM!B30)=0, "ISM", "ALL") -> ISM | B30: EPS_MMDSTATETIME_DAY | D30: History | E30: GC_MES_HIST_DAT
A31: =IF(COUNTIFS(테이블_SIP!$B$2:$B$214, 테이블_ISM!B31)=0, "ISM", "ALL") -> ISM | B31: EQPMEASUREDATA | D31: Master | E31: DXPLUS
A32: =IF(COUNTIFS(테이블_SIP!$B$2:$B$214, 테이블_ISM!B32)=0, "ISM", "ALL") -> ISM | B32: EQPMEASUREDATAHISTORY | D32: History | E32: GC_MES_HIST_DAT | F32: GC_MES_HIST_IDX
A33: =IF(COUNTIFS(테이블_SIP!$B$2:$B$214, 테이블_ISM!B33)=0, "ISM", "ALL") -> ISM | B33: EQPPREVENTPLAN | D33: Master | E33: GC_MES_MDM_DAT | F33: GC_MES_MDM_IDX
A34: =IF(COUNTIFS(테이블_SIP!$B$2:$B$214, 테이블_ISM!B34)=0, "ISM", "ALL") -> ISM | B34: EQPPREVENTPLANHISTORY | D34: Master | E34: GC_MES_MDM_DAT | F34: GC_MES_MDM_IDX
A35: =IF(COUNTIFS(테이블_SIP!$B$2:$B$214, 테이블_ISM!B35)=0, "ISM", "ALL") -> ALL | B35: EQUIPMENT | C35: 설비 ID 정의 | D35: Master | E35: GC_MES_STD_DAT | F35: GC_MES_STD_IDX
A36: =IF(COUNTIFS(테이블_SIP!$B$2:$B$214, 테이블_ISM!B36)=0, "ISM", "ALL") -> ISM | B36: EQUIPMENTBMDATA | D36: Master | E36: GC_MES_MDM_DAT | F36: GC_MES_MDM_IDX
A37: =IF(COUNTIFS(테이블_SIP!$B$2:$B$214, 테이블_ISM!B37)=0, "ISM", "ALL") -> ISM | B37: EQUIPMENTBMDATAHISTORY | D37: History | E37: GC_MES_HIST_DAT | F37: GC_MES_HIST_IDX
A38: =IF(COUNTIFS(테이블_SIP!$B$2:$B$214, 테이블_ISM!B38)=0, "ISM", "ALL") -> ISM | B38: EQUIPMENTCOMMSTATE | C38: 설비통신상태 기준정보 | D38: Master | E38: GC_MES_STD_DAT | F38: GC_MES_STD_IDX
A39: =IF(COUNTIFS(테이블_SIP!$B$2:$B$214, 테이블_ISM!B39)=0, "ISM", "ALL") -> ISM | B39: EQUIPMENTCOMMSTATEHISTORY | C39: 설비통신상태 기준정보 | D39: History | E39: GC_MES_HIST_DAT | F39: GC_MES_HIST_IDX
A40: =IF(COUNTIFS(테이블_SIP!$B$2:$B$214, 테이블_ISM!B40)=0, "ISM", "ALL") -> ALL | B40: EQUIPMENTDEF | C40: 설비코드 기준정보 | D40: Master | E40: GC_MES_MDM_DAT | F40: GC_MES_MDM_IDX
...

Sheet 테이블_SIP
A1: 테이블 존재 | B1: TABLE_NAME | C1: COMMENTS | D1: CURHIST | E1: TABLESPACE_TABLE | F1: TABLESPACE_INDEX | G1: PARTITION_BY
A2: =IF(COUNTIFS(테이블_ISM!$B$2:$B$260, 테이블_SIP!B2)=0, "SIP", "ALL") -> SIP | B2: ALARM | D2: Master | E2: SIPMES | F2: USERS
A3: =IF(COUNTIFS(테이블_ISM!$B$2:$B$260, 테이블_SIP!B3)=0, "SIP", "ALL") -> SIP | B3: ALARMACTION | D3: Master | E3: SIPMES | F3: USERS
A4: =IF(COUNTIFS(테이블_ISM!$B$2:$B$260, 테이블_SIP!B4)=0, "SIP", "ALL") -> SIP | B4: ALARMACTIONHISTORY | D4: Master | E4: SIPMES | F4: USERS
A5: =IF(COUNTIFS(테이블_ISM!$B$2:$B$260, 테이블_SIP!B5)=0, "SIP", "ALL") -> SIP | B5: ALARMCODE | D5: Master | E5: USERS | F5: USERS
A6: =IF(COUNTIFS(테이블_ISM!$B$2:$B$260, 테이블_SIP!B6)=0, "SIP", "ALL") -> SIP | B6: ALARMCODEHISTORY | D6: Master | E6: SIPMES
A7: =IF(COUNTIFS(테이블_ISM!$B$2:$B$260, 테이블_SIP!B7)=0, "SIP", "ALL") -> SIP | B7: ALARMGROUP | D7: Master | E7: SIPMES | F7: USERS
A8: =IF(COUNTIFS(테이블_ISM!$B$2:$B$260, 테이블_SIP!B8)=0, "SIP", "ALL") -> SIP | B8: ALARMGROUPHISTORY | D8: Master | E8: SIPMES | F8: USERS
A9: =IF(COUNTIFS(테이블_ISM!$B$2:$B$260, 테이블_SIP!B9)=0, "SIP", "ALL") -> SIP | B9: ALARMHISTORY | D9: Master | E9: SIPMES | F9: USERS
A10: =IF(COUNTIFS(테이블_ISM!$B$2:$B$260, 테이블_SIP!B10)=0, "SIP", "ALL") -> SIP | B10: ALARMSCOPE | D10: Master | E10: SIPMES | F10: USERS
A11: =IF(COUNTIFS(테이블_ISM!$B$2:$B$260, 테이블_SIP!B11)=0, "SIP", "ALL") -> SIP | B11: ALARMSCOPEHISTORY | D11: Master | E11: SIPMES | F11: USERS
A12: =IF(COUNTIFS(테이블_ISM!$B$2:$B$260, 테이블_SIP!B12)=0, "SIP", "ALL") -> ALL | B12: AREA | C12: 생산 영역 기준정보 | D12: Master | E12: GC_MES_MDM_DAT | F12: SIPMES
A13: =IF(COUNTIFS(테이블_ISM!$B$2:$B$260, 테이블_SIP!B13)=0, "SIP", "ALL") -> ALL | B13: AREAHISTORY | C13: 생산 영역 기준정보 이력 | D13: History | E13: GC_MES_HIST_DAT | F13: SIPMES
A14: =IF(COUNTIFS(테이블_ISM!$B$2:$B$260, 테이블_SIP!B14)=0, "SIP", "ALL") -> ALL | B14: ATTRIBUTE | C14: 기준정보 공통UI 그리드항목 모델링 기준정보 | D14: Master | E14: GC_MES_MDM_DAT | F14: SIPMES_251229
A15: =IF(COUNTIFS(테이블_ISM!$B$2:$B$260, 테이블_SIP!B15)=0, "SIP", "ALL") -> ALL | B15: ATTRIBUTEHISTORY | C15: 기준정보 공통UI 그리드항목 모델링 기준정보 | D15: History | E15: GC_MES_HIST_DAT | F15: SIPMES
A16: =IF(COUNTIFS(테이블_ISM!$B$2:$B$260, 테이블_SIP!B16)=0, "SIP", "ALL") -> ALL | B16: AUTHOR | C16: 권한ID 기준정보 | D16: Master | E16: GC_MES_MDM_DAT | F16: SIPMES
A17: =IF(COUNTIFS(테이블_ISM!$B$2:$B$260, 테이블_SIP!B17)=0, "SIP", "ALL") -> ALL | B17: AUTHORHISTORY | C17: 권한그룹ID 기준정보 | D17: History | E17: GC_MES_HIST_DAT | F17: SIPMES
A18: =IF(COUNTIFS(테이블_ISM!$B$2:$B$260, 테이블_SIP!B18)=0, "SIP", "ALL") -> ALL | B18: AUTHORMENU | C18: 권한그룹별 메뉴권한 매핑정보 | D18: Master | E18: GC_MES_MDM_DAT | F18: SIPMES_251229
A19: =IF(COUNTIFS(테이블_ISM!$B$2:$B$260, 테이블_SIP!B19)=0, "SIP", "ALL") -> ALL | B19: AUTHORMENUHISTORY | C19: 권한그룹별 메뉴권한 매핑정보 | D19: History | E19: GC_MES_HIST_DAT | F19: SIPMES
A20: =IF(COUNTIFS(테이블_ISM!$B$2:$B$260, 테이블_SIP!B20)=0, "SIP", "ALL") -> ALL | B20: AUTHREASONCODE | C20: 권한별 사유코드 관리 | D20: Master | E20: GC_MES_MDM_DAT | F20: SIPMES
A21: =IF(COUNTIFS(테이블_ISM!$B$2:$B$260, 테이블_SIP!B21)=0, "SIP", "ALL") -> ALL | B21: AUTHREASONCODEHISTORY | D21: Master | E21: GC_MES_MDM_DAT | F21: SIPMES
A22: =IF(COUNTIFS(테이블_ISM!$B$2:$B$260, 테이블_SIP!B22)=0, "SIP", "ALL") -> ALL | B22: BEHAVIOR | C22: 기준정보 공통UI 그리드항목 모델링 기준정보 | D22: Master | E22: GC_MES_MDM_DAT | F22: SIPMES_251229
A23: =IF(COUNTIFS(테이블_ISM!$B$2:$B$260, 테이블_SIP!B23)=0, "SIP", "ALL") -> ALL | B23: BEHAVIORHISTORY | C23: 기준정보 공통UI 그리드항목 모델링 기준정보 | D23: History | E23: GC_MES_HIST_DAT | F23: SIPMES
A24: =IF(COUNTIFS(테이블_ISM!$B$2:$B$260, 테이블_SIP!B24)=0, "SIP", "ALL") -> ALL | B24: CARRIER | C24: 캐리어 ID 정보 | D24: Master | E24: GC_MES_STD_DAT | F24: SIPMES
A25: =IF(COUNTIFS(테이블_ISM!$B$2:$B$260, 테이블_SIP!B25)=0, "SIP", "ALL") -> ALL | B25: CARRIERDEF | C25: 캐리어 기준정보 | D25: Master | E25: GC_MES_MDM_DAT | F25: SIPMES
A26: =IF(COUNTIFS(테이블_ISM!$B$2:$B$260, 테이블_SIP!B26)=0, "SIP", "ALL") -> ALL | B26: CARRIERDEFHISTORY | C26: 캐리어 기준정보 이력 | D26: History | E26: GC_MES_HIST_DAT | F26: SIPMES
A27: =IF(COUNTIFS(테이블_ISM!$B$2:$B$260, 테이블_SIP!B27)=0, "SIP", "ALL") -> ALL | B27: CARRIERHISTORY | C27: 캐리어 기준정보 이력 | D27: History | E27: GC_MES_HIST_DAT | F27: SIPMES
A28: =IF(COUNTIFS(테이블_ISM!$B$2:$B$260, 테이블_SIP!B28)=0, "SIP", "ALL") -> SIP | B28: CHECKINLINE | C28: ^Available^STND^RT^RESOURCE^Current^^Off^ACM | D28: Master | E28: GC_MES_MDM_DAT | F28: GC_MES_MDM_DAT
A29: =IF(COUNTIFS(테이블_ISM!$B$2:$B$260, 테이블_SIP!B29)=0, "SIP", "ALL") -> SIP | B29: CHECKINLINEHISTORY | D29: Master | E29: GC_MES_MDM_DAT | F29: GC_MES_MDM_DAT
A30: =IF(COUNTIFS(테이블_ISM!$B$2:$B$260, 테이블_SIP!B30)=0, "SIP", "ALL") -> SIP | B30: CLIENT | D30: Master | E30: USERS | F30: USERS
A31: =IF(COUNTIFS(테이블_ISM!$B$2:$B$260, 테이블_SIP!B31)=0, "SIP", "ALL") -> SIP | B31: CLIENTHISTORY | D31: Master | E31: USERS | F31: USERS
A32: =IF(COUNTIFS(테이블_ISM!$B$2:$B$260, 테이블_SIP!B32)=0, "SIP", "ALL") -> SIP | B32: CLIENT_LOG | C32: 클라이언트 로그 저장 테이블 | D32: Master | E32: SIPMES_251229 | F32: SIPMES_251229
A33: =IF(COUNTIFS(테이블_ISM!$B$2:$B$260, 테이블_SIP!B33)=0, "SIP", "ALL") -> ALL | B33: COLUMNDEF | D33: Master | E33: GC_MES_MDM_DAT
A34: =IF(COUNTIFS(테이블_ISM!$B$2:$B$260, 테이블_SIP!B34)=0, "SIP", "ALL") -> ALL | B34: CONSUMABLELOT | D34: Master | E34: GC_MES_STD_DAT | F34: SIPMES
A35: =IF(COUNTIFS(테이블_ISM!$B$2:$B$260, 테이블_SIP!B35)=0, "SIP", "ALL") -> ALL | B35: CONSUMABLELOTHISTORY | D35: History | E35: GC_MES_HIST_DAT | F35: SIPMES
A36: =IF(COUNTIFS(테이블_ISM!$B$2:$B$260, 테이블_SIP!B36)=0, "SIP", "ALL") -> SIP | B36: DEFECTSUMMARY | D36: Master | E36: USERS | F36: USERS
A37: =IF(COUNTIFS(테이블_ISM!$B$2:$B$260, 테이블_SIP!B37)=0, "SIP", "ALL") -> SIP | B37: DEFECTSUMMARYHISTORY | D37: Master | E37: USERS | F37: USERS
A38: =IF(COUNTIFS(테이블_ISM!$B$2:$B$260, 테이블_SIP!B38)=0, "SIP", "ALL") -> SIP | B38: DEFECTYIELDHISTORY | D38: Master | E38: USERS | F38: USERS
A39: =IF(COUNTIFS(테이블_ISM!$B$2:$B$260, 테이블_SIP!B39)=0, "SIP", "ALL") -> ALL | B39: DURABLELOT | C39: Durable자재 LOT 정보 | D39: Master | E39: GC_MES_STD_DAT | F39: SIPMES
A40: =IF(COUNTIFS(테이블_ISM!$B$2:$B$260, 테이블_SIP!B40)=0, "SIP", "ALL") -> ALL | B40: DURABLELOTHISTORY | C40: Durable자재LOT 정보 이력 | D40: History | E40: GC_MES_HIST_DAT
...

Sheet 컬럼_ISM
A1: 테이블 존재 | B1: 컬럼 존재 | C1: TAB+COL | D1: TAB_NAME | E1: COL_NAME | F1: COL_ID | G1: TYPE | H1: LENGTH | I1: NULLABLE | J1: PK | K1: COMMENTS
A2: =IF(COUNTIFS(컬럼_SIP!$D$2:$D$4718, 컬럼_ISM!D2)=0, "ISM", "ALL") -> ALL | B2: =IF(COUNTIFS(컬럼_SIP!$C$2:$C$4718, 컬럼_ISM!C2)=0, "ISM", "ALL") -> ALL | C2: =D2&"+"&E2 -> AREA+AREAID | D2: AREA | E2: AREAID | F2: 1 | G2: VARCHAR2 | H2: 40 | I2: N | J2: PK | K2: 영역 Id :
A3: =IF(COUNTIFS(컬럼_SIP!$D$2:$D$4718, 컬럼_ISM!D3)=0, "ISM", "ALL") -> ALL | B3: =IF(COUNTIFS(컬럼_SIP!$C$2:$C$4718, 컬럼_ISM!C3)=0, "ISM", "ALL") -> ALL | C3: =D3&"+"&E3 -> AREA+DESCRIPTION | D3: AREA | E3: DESCRIPTION | F3: 2 | G3: VARCHAR2 | H3: 400 | I3: Y | K3: 설명 :
A4: =IF(COUNTIFS(컬럼_SIP!$D$2:$D$4718, 컬럼_ISM!D4)=0, "ISM", "ALL") -> ALL | B4: =IF(COUNTIFS(컬럼_SIP!$C$2:$C$4718, 컬럼_ISM!C4)=0, "ISM", "ALL") -> ALL | C4: =D4&"+"&E4 -> AREA+AREATYPE | D4: AREA | E4: AREATYPE | F4: 3 | G4: VARCHAR2 | H4: 40 | I4: Y | K4: 영역 종류 :Production/Storage
A5: =IF(COUNTIFS(컬럼_SIP!$D$2:$D$4718, 컬럼_ISM!D5)=0, "ISM", "ALL") -> ALL | B5: =IF(COUNTIFS(컬럼_SIP!$C$2:$C$4718, 컬럼_ISM!C5)=0, "ISM", "ALL") -> ALL | C5: =D5&"+"&E5 -> AREA+FACTORYID | D5: AREA | E5: FACTORYID | F5: 4 | G5: VARCHAR2 | H5: 40 | I5: Y | K5: 공장 명 :
A6: =IF(COUNTIFS(컬럼_SIP!$D$2:$D$4718, 컬럼_ISM!D6)=0, "ISM", "ALL") -> ALL | B6: =IF(COUNTIFS(컬럼_SIP!$C$2:$C$4718, 컬럼_ISM!C6)=0, "ISM", "ALL") -> ALL | C6: =D6&"+"&E6 -> AREA+ROOTAREAID | D6: AREA | E6: ROOTAREAID | F6: 5 | G6: VARCHAR2 | H6: 40 | I6: Y | K6: Root AreaId :
A7: =IF(COUNTIFS(컬럼_SIP!$D$2:$D$4718, 컬럼_ISM!D7)=0, "ISM", "ALL") -> ALL | B7: =IF(COUNTIFS(컬럼_SIP!$C$2:$C$4718, 컬럼_ISM!C7)=0, "ISM", "ALL") -> ALL | C7: =D7&"+"&E7 -> AREA+PARENTAREAID | D7: AREA | E7: PARENTAREAID | F7: 6 | G7: VARCHAR2 | H7: 40 | I7: Y | K7: 상위 AreaId :
A8: =IF(COUNTIFS(컬럼_SIP!$D$2:$D$4718, 컬럼_ISM!D8)=0, "ISM", "ALL") -> ALL | B8: =IF(COUNTIFS(컬럼_SIP!$C$2:$C$4718, 컬럼_ISM!C8)=0, "ISM", "ALL") -> ALL | C8: =D8&"+"&E8 -> AREA+DETAILAREATYPE | D8: AREA | E8: DETAILAREATYPE | F8: 7 | G8: VARCHAR2 | H8: 40 | I8: Y | K8: Area 레벨 Type :Area/SubArea/Bay
A9: =IF(COUNTIFS(컬럼_SIP!$D$2:$D$4718, 컬럼_ISM!D9)=0, "ISM", "ALL") -> ALL | B9: =IF(COUNTIFS(컬럼_SIP!$C$2:$C$4718, 컬럼_ISM!C9)=0, "ISM", "ALL") -> ALL | C9: =D9&"+"&E9 -> AREA+CHECKOUTSTATE | D9: AREA | E9: CHECKOUTSTATE | F9: 8 | G9: VARCHAR2 | H9: 40 | I9: Y | K9: User별 데이터 편집상태 :
A10: =IF(COUNTIFS(컬럼_SIP!$D$2:$D$4718, 컬럼_ISM!D10)=0, "ISM", "ALL") -> ALL | B10: =IF(COUNTIFS(컬럼_SIP!$C$2:$C$4718, 컬럼_ISM!C10)=0, "ISM", "ALL") -> ALL | C10: =D10&"+"&E10 -> AREA+CHECKOUTTIME | D10: AREA | E10: CHECKOUTTIME | F10: 9 | G10: DATE | H10: 7 | I10: Y | K10: 데이터 편집위해 CheckOut시간 :
A11: =IF(COUNTIFS(컬럼_SIP!$D$2:$D$4718, 컬럼_ISM!D11)=0, "ISM", "ALL") -> ALL | B11: =IF(COUNTIFS(컬럼_SIP!$C$2:$C$4718, 컬럼_ISM!C11)=0, "ISM", "ALL") -> ALL | C11: =D11&"+"&E11 -> AREA+CHECKOUTUSER | D11: AREA | E11: CHECKOUTUSER | F11: 10 | G11: VARCHAR2 | H11: 40 | I11: Y | K11: CheckOut UserId :
A12: =IF(COUNTIFS(컬럼_SIP!$D$2:$D$4718, 컬럼_ISM!D12)=0, "ISM", "ALL") -> ALL | B12: =IF(COUNTIFS(컬럼_SIP!$C$2:$C$4718, 컬럼_ISM!C12)=0, "ISM", "ALL") -> ALL | C12: =D12&"+"&E12 -> AREA+DATASTATE | D12: AREA | E12: DATASTATE | F12: 11 | G12: VARCHAR2 | H12: 10 | I12: Y | K12: 변경 상태 :
A13: =IF(COUNTIFS(컬럼_SIP!$D$2:$D$4718, 컬럼_ISM!D13)=0, "ISM", "ALL") -> ALL | B13: =IF(COUNTIFS(컬럼_SIP!$C$2:$C$4718, 컬럼_ISM!C13)=0, "ISM", "ALL") -> ALL | C13: =D13&"+"&E13 -> AREA+EVENT | D13: AREA | E13: EVENT | F13: 12 | G13: VARCHAR2 | H13: 40 | I13: Y | K13: 이벤트 :
A14: =IF(COUNTIFS(컬럼_SIP!$D$2:$D$4718, 컬럼_ISM!D14)=0, "ISM", "ALL") -> ALL | B14: =IF(COUNTIFS(컬럼_SIP!$C$2:$C$4718, 컬럼_ISM!C14)=0, "ISM", "ALL") -> ALL | C14: =D14&"+"&E14 -> AREA+TIMEKEY | D14: AREA | E14: TIMEKEY | F14: 13 | G14: VARCHAR2 | H14: 40 | I14: Y | K14: 타임 키 :
... A19: =IF(COUNTIFS(컬럼_SIP!$D$2:$D$4718, 컬럼_ISM!D19)=0, "ISM", "ALL") -> ALL | B19: =IF(COUNTIFS(컬럼_SIP!$C$2:$C$4718, 컬럼_ISM!C19)=0, "ISM", "ALL") -> ALL | C19: =D19&"+"&E19 -> AREA+LINEID | D19: AREA | E19: LINEID | F19: 18 | G19: VARCHAR2 | H19: 40 | I19: Y | K19: LINE 정보 (BUMP, EDS)
A20: =IF(COUNTIFS(컬럼_SIP!$D$2:$D$4718, 컬럼_ISM!D20)=0, "ISM", "ALL") -> ALL | B20: =IF(COUNTIFS(컬럼_SIP!$C$2:$C$4718, 컬럼_ISM!C20)=0, "ISM", "ALL") -> ALL | C20: =D20&"+"&E20 -> AREAHISTORY+AREAID | D20: AREAHISTORY | E20: AREAID | F20: 1 | G20: VARCHAR2 | H20: 40 | I20: N | J20: PK | K20: 영역 Id :
A21: =IF(COUNTIFS(컬럼_SIP!$D$2:$D$4718, 컬럼_ISM!D21)=0, "ISM", "ALL") -> ALL | B21: =IF(COUNTIFS(컬럼_SIP!$C$2:$C$4718, 컬럼_ISM!C21)=0, "ISM", "ALL") -> ALL | C21: =D21&"+"&E21 -> AREAHISTORY+DESCRIPTION | D21: AREAHISTORY | E21: DESCRIPTION | F21: 2 | G21: VARCHAR2 | H21: 400 | I21: Y | K21: 설명 :
A22: =IF(COUNTIFS(컬럼_SIP!$D$2:$D$4718, 컬럼_ISM!D22)=0, "ISM", "ALL") -> ALL | B22: =IF(COUNTIFS(컬럼_SIP!$C$2:$C$4718, 컬럼_ISM!C22)=0, "ISM", "ALL") -> ALL | C22: =D22&"+"&E22 -> AREAHISTORY+AREATYPE | D22: AREAHISTORY | E22: AREATYPE | F22: 3 | G22: VARCHAR2 | H22: 40 | I22: Y | K22: 영역 종류 :Production/Storage
A23: =IF(COUNTIFS(컬럼_SIP!$D$2:$D$4718, 컬럼_ISM!D23)=0, "ISM", "ALL") -> ALL | B23: =IF(COUNTIFS(컬럼_SIP!$C$2:$C$4718, 컬럼_ISM!C23)=0, "ISM", "ALL") -> ALL | C23: =D23&"+"&E23 -> AREAHISTORY+FACTORYID | D23: AREAHISTORY | E23: FACTORYID | F23: 4 | G23: VARCHAR2 | H23: 40 | I23: Y | K23: 공장 명 :
A24: =IF(COUNTIFS(컬럼_SIP!$D$2:$D$4718, 컬럼_ISM!D24)=0, "ISM", "ALL") -> ALL | B24: =IF(COUNTIFS(컬럼_SIP!$C$2:$C$4718, 컬럼_ISM!C24)=0, "ISM", "ALL") -> ALL | C24: =D24&"+"&E24 -> AREAHISTORY+ROOTAREAID | D24: AREAHISTORY | E24: ROOTAREAID | F24: 5 | G24: VARCHAR2 | H24: 40 | I24: Y | K24: Root AreaId :
A25: =IF(COUNTIFS(컬럼_SIP!$D$2:$D$4718, 컬럼_ISM!D25)=0, "ISM", "ALL") -> ALL | B25: =IF(COUNTIFS(컬럼_SIP!$C$2:$C$4718, 컬럼_ISM!C25)=0, "ISM", "ALL") -> ALL | C25: =D25&"+"&E25 -> AREAHISTORY+PARENTAREAID | D25: AREAHISTORY | E25: PARENTAREAID | F25: 6 | G25: VARCHAR2 | H25: 40 | I25: Y | K25: 상위 AreaId :
A26: =IF(COUNTIFS(컬럼_SIP!$D$2:$D$4718, 컬럼_ISM!D26)=0, "ISM", "ALL") -> ALL | B26: =IF(COUNTIFS(컬럼_SIP!$C$2:$C$4718, 컬럼_ISM!C26)=0, "ISM", "ALL") -> ALL | C26: =D26&"+"&E26 -> AREAHISTORY+DETAILAREATYPE | D26: AREAHISTORY | E26: DETAILAREATYPE | F26: 7 | G26: VARCHAR2 | H26: 40 | I26: Y | K26: Area 레벨 Type :Area/SubArea/Bay
A27: =IF(COUNTIFS(컬럼_SIP!$D$2:$D$4718, 컬럼_ISM!D27)=0, "ISM", "ALL") -> ALL | B27: =IF(COUNTIFS(컬럼_SIP!$C$2:$C$4718, 컬럼_ISM!C27)=0, "ISM", "ALL") -> ALL | C27: =D27&"+"&E27 -> AREAHISTORY+CHECKOUTSTATE | D27: AREAHISTORY | E27: CHECKOUTSTATE | F27: 8 | G27: VARCHAR2 | H27: 40 | I27: Y | K27: User별 데이터 편집상태 :
A28: =IF(COUNTIFS(컬럼_SIP!$D$2:$D$4718, 컬럼_ISM!D28)=0, "ISM", "ALL") -> ALL | B28: =IF(COUNTIFS(컬럼_SIP!$C$2:$C$4718, 컬럼_ISM!C28)=0, "ISM", "ALL") -> ALL | C28: =D28&"+"&E28 -> AREAHISTORY+CHECKOUTTIME | D28: AREAHISTORY | E28: CHECKOUTTIME | F28: 9 | G28: DATE | H28: 7 | I28: Y | K28: 데이터 편집위해 CheckOut시간 :
A29: =IF(COUNTIFS(컬럼_SIP!$D$2:$D$4718, 컬럼_ISM!D29)=0, "ISM", "ALL") -> ALL | B29: =IF(COUNTIFS(컬럼_SIP!$C$2:$C$4718, 컬럼_ISM!C29)=0, "ISM", "ALL") -> ALL | C29: =D29&"+"&E29 -> AREAHISTORY+CHECKOUTUSER | D29: AREAHISTORY | E29: CHECKOUTUSER | F29: 10 | G29: VARCHAR2 | H29: 40 | I29: Y | K29: CheckOut UserId :
A30: =IF(COUNTIFS(컬럼_SIP!$D$2:$D$4718, 컬럼_ISM!D30)=0, "ISM", "ALL") -> ALL | B30: =IF(COUNTIFS(컬럼_SIP!$C$2:$C$4718, 컬럼_ISM!C30)=0, "ISM", "ALL") -> ALL | C30: =D30&"+"&E30 -> AREAHISTORY+DATASTATE | D30: AREAHISTORY | E30: DATASTATE | F30: 11 | G30: VARCHAR2 | H30: 10 | I30: Y | K30: 변경 상태 :
A31: =IF(COUNTIFS(컬럼_SIP!$D$2:$D$4718, 컬럼_ISM!D31)=0, "ISM", "ALL") -> ALL | B31: =IF(COUNTIFS(컬럼_SIP!$C$2:$C$4718, 컬럼_ISM!C31)=0, "ISM", "ALL") -> ALL | C31: =D31&"+"&E31 -> AREAHISTORY+EVENT | D31: AREAHISTORY | E31: EVENT | F31: 12 | G31: VARCHAR2 | H31: 40 | I31: Y | K31: 이벤트 :
A32: =IF(COUNTIFS(컬럼_SIP!$D$2:$D$4718, 컬럼_ISM!D32)=0, "ISM", "ALL") -> ALL | B32: =IF(COUNTIFS(컬럼_SIP!$C$2:$C$4718, 컬럼_ISM!C32)=0, "ISM", "ALL") -> ALL | C32: =D32&"+"&E32 -> AREAHISTORY+TIMEKEY | D32: AREAHISTORY | E32: TIMEKEY | F32: 13 | G32: VARCHAR2 | H32: 40 | I32: N | J32: PK | K32: 타임 키 :
A33: =IF(COUNTIFS(컬럼_SIP!$D$2:$D$4718, 컬럼_ISM!D33)=0, "ISM", "ALL") -> ALL | B33: =IF(COUNTIFS(컬럼_SIP!$C$2:$C$4718, 컬럼_ISM!C33)=0, "ISM", "ALL") -> ALL | C33: =D33&"+"&E33 -> AREAHISTORY+EVENTTIME | D33: AREAHISTORY | E33: EVENTTIME | F33: 14 | G33: DATE | H33: 7 | I33: Y | K33: 시각 :
A34: =IF(COUNTIFS(컬럼_SIP!$D$2:$D$4718, 컬럼_ISM!D34)=0, "ISM", "ALL") -> ALL | B34: =IF(COUNTIFS(컬럼_SIP!$C$2:$C$4718, 컬럼_ISM!C34)=0, "ISM", "ALL") -> ALL | C34: =D34&"+"&E34 -> AREAHISTORY+MESSAGE | D34: AREAHISTORY | E34: MESSAGE | F34: 15 | G34: VARCHAR2 | H34: 40 | I34: Y | K34: 메시지 :
A35: =IF(COUNTIFS(컬럼_SIP!$D$2:$D$4718, 컬럼_ISM!D35)=0, "ISM", "ALL") -> ALL | B35: =IF(COUNTIFS(컬럼_SIP!$C$2:$C$4718, 컬럼_ISM!C35)=0, "ISM", "ALL") -> ALL | C35: =D35&"+"&E35 -> AREAHISTORY+EVENTUSER | D35: AREAHISTORY | E35: EVENTUSER | F35: 16 | G35: VARCHAR2 | H35: 40 | I35: Y | K35: 사용자 :
A36: =IF(COUNTIFS(컬럼_SIP!$D$2:$D$4718, 컬럼_ISM!D36)=0, "ISM", "ALL") -> ALL | B36: =IF(COUNTIFS(컬럼_SIP!$C$2:$C$4718, 컬럼_ISM!C36)=0, "ISM", "ALL") -> ALL | C36: =D36&"+"&E36 -> AREAHISTORY+EVENTCOMMENT | D36: AREAHISTORY | E36: EVENTCOMMENT | F36: 17 | G36: VARCHAR2 | H36: 500 | I36: Y | K36: System 커맨트 :
A37: =IF(COUNTIFS(컬럼_SIP!$D$2:$D$4718, 컬럼_ISM!D37)=0, "ISM", "ALL") -> ALL | B37: =IF(COUNTIFS(컬럼_SIP!$C$2:$C$4718, 컬럼_ISM!C37)=0, "ISM", "ALL") -> ALL | C37: =D37&"+"&E37 -> AREAHISTORY+LINEID | D37: AREAHISTORY | E37: LINEID | F37: 18 | G37: VARCHAR2 | H37: 40 | I37: Y | K37: LINE 정보 (BUMP, EDS)
A38: =IF(COUNTIFS(컬럼_SIP!$D$2:$D$4718, 컬럼_ISM!D38)=0, "ISM", "ALL") -> ALL | B38: =IF(COUNTIFS(컬럼_SIP!$C$2:$C$4718, 컬럼_ISM!C38)=0, "ISM", "ALL") -> ALL | C38: =D38&"+"&E38 -> ATTRIBUTE+BEHAVIORNAME | D38: ATTRIBUTE | E38: BEHAVIORNAME | F38: 1 | G38: VARCHAR2 | H38: 40 | I38: N | J38: PK | K38: ATTRIBUTE 유형
A39: =IF(COUNTIFS(컬럼_SIP!$D$2:$D$4718, 컬럼_ISM!D39)=0, "ISM", "ALL") -> ALL | B39: =IF(COUNTIFS(컬럼_SIP!$C$2:$C$4718, 컬럼_ISM!C39)=0, "ISM", "ALL") -> ALL | C39: =D39&"+"&E39 -> ATTRIBUTE+ATTRIBUTENAME | D39: ATTRIBUTE | E39: ATTRIBUTENAME | F39: 2 | G39: VARCHAR2 | H39: 40 | I39: N | J39: PK | K39: ATTRIBUTE 이름
A40: =IF(COUNTIFS(컬럼_SIP!$D$2:$D$4718, 컬럼_ISM!D40)=0, "ISM", "ALL") -> ALL | B40: =IF(COUNTIFS(컬럼_SIP!$C$2:$C$4718, 컬럼_ISM!C40)=0, "ISM", "ALL") -> ALL | C40: =D40&"+"&E40 -> ATTRIBUTE+POSITION | D40: ATTRIBUTE | E40: POSITION | F40: 3 | G40: NUMBER | H40: 22 | I40: Y | K40: 순서
A41: =IF(COUNTIFS(컬럼_SIP!$D$2:$D$4718, 컬럼_ISM!D41)=0, "ISM", "ALL") -> ALL | B41: =IF(COUNTIFS(컬럼_SIP!$C$2:$C$4718, 컬럼_ISM!C41)=0, "ISM", "ALL") -> ALL | C41: =D41&"+"&E41 -> ATTRIBUTE+DESCRIPTION | D41: ATTRIBUTE | E41: DESCRIPTION | F41: 4 | G41: VARCHAR2 | H41: 400 | I41: Y | K41: 설명
A42: =IF(COUNTIFS(컬럼_SIP!$D$2:$D$4718, 컬럼_ISM!D42)=0, "ISM", "ALL") -> ALL | B42: =IF(COUNTIFS(컬럼_SIP!$C$2:$C$4718, 컬럼_ISM!C42)=0, "ISM", "ALL") -> ALL | C42: =D42&"+"&E42 -> ATTRIBUTE+KEYFLAG | D42: ATTRIBUTE | E42: KEYFLAG | F42: 5 | G42: VARCHAR2 | H42: 1 | I42: Y | K42: 키 값 여부
A43: =IF(COUNTIFS(컬럼_SIP!$D$2:$D$4718, 컬럼_ISM!D43)=0, "ISM", "ALL") -> ALL | B43: =IF(COUNTIFS(컬럼_SIP!$C$2:$C$4718, 컬럼_ISM!C43)=0, "ISM", "ALL") -> ALL | C43: =D43&"+"&E43 -> ATTRIBUTE+DATATYPE | D43: ATTRIBUTE | E43: DATATYPE | F43: 6 | G43: VARCHAR2 | H43: 40 | I43: Y | K43: 데이터 유형
A44: =IF(COUNTIFS(컬럼_SIP!$D$2:$D$4718, 컬럼_ISM!D44)=0, "ISM", "ALL") -> ALL | B44: =IF(COUNTIFS(컬럼_SIP!$C$2:$C$4718, 컬럼_ISM!C44)=0, "ISM", "ALL") -> ALL | C44: =D44&"+"&E44 -> ATTRIBUTE+DEFAULTVALUE | D44: ATTRIBUTE | E44: DEFAULTVALUE | F44: 7 | G44: VARCHAR2 | H44: 400 | I44: Y | K44: 기본 값
...

Sheet 컬럼_SIP
A1: 테이블 존재 | B1: 컬럼 존재 | C1: TAB+COL | D1: TAB_NAME | E1: COL_NAME | F1: COL_ID | G1: TYPE | H1: LENGTH | I1: NULLABLE | J1: PK | K1: COMMENTS
A2: =IF(COUNTIFS(컬럼_ISM!$D$2:$D$5176, 컬럼_SIP!D2)=0, "SIP", "ALL") -> SIP | B2: =IF(COUNTIFS(컬럼_ISM!$C$2:$C$5176, 컬럼_SIP!C2)=0, "SIP", "ALL") -> SIP | C2: =D2&"+"&E2 -> ALARM+ALARMID | D2: ALARM | E2: ALARMID | F2: 1 | G2: VARCHAR2 | H2: 40 | I2: N | J2: PK | K2: 발생한 ALARM별 Unique한 ID
A3: =IF(COUNTIFS(컬럼_ISM!$D$2:$D$5176, 컬럼_SIP!D3)=0, "SIP", "ALL") -> SIP | B3: =IF(COUNTIFS(컬럼_ISM!$C$2:$C$5176, 컬럼_SIP!C3)=0, "SIP", "ALL") -> SIP | C3: =D3&"+"&E3 -> ALARM+FACTORYID | D3: ALARM | E3: FACTORYID | F3: 2 | G3: VARCHAR2 | H3: 40 | I3: N | J3: PK | K3: 공장 ID
A4: =IF(COUNTIFS(컬럼_ISM!$D$2:$D$5176, 컬럼_SIP!D4)=0, "SIP", "ALL") -> SIP | B4: =IF(COUNTIFS(컬럼_ISM!$C$2:$C$5176, 컬럼_SIP!C4)=0, "SIP", "ALL") -> SIP | C4: =D4&"+"&E4 -> ALARM+ALARMGROUPID | D4: ALARM | E4: ALARMGROUPID | F4: 3 | G4: VARCHAR2 | H4: 40 | I4: Y | K4: ALARM을 발생시키는 곳 (EQP, SPC, SYSTEM)
A5: =IF(COUNTIFS(컬럼_ISM!$D$2:$D$5176, 컬럼_SIP!D5)=0, "SIP", "ALL") -> SIP | B5: =IF(COUNTIFS(컬럼_ISM!$C$2:$C$5176, 컬럼_SIP!C5)=0, "SIP", "ALL") -> SIP | C5: =D5&"+"&E5 -> ALARM+ALARMLEVEL | D5: ALARM | E5: ALARMLEVEL | F5: 4 | G5: VARCHAR2 | H5: 40 | I5: Y | K5: ALARM 등급에 대한 Level(INFO, WARNING, ALARM)
A6: =IF(COUNTIFS(컬럼_ISM!$D$2:$D$5176, 컬럼_SIP!D6)=0, "SIP", "ALL") -> SIP | B6: =IF(COUNTIFS(컬럼_ISM!$C$2:$C$5176, 컬럼_SIP!C6)=0, "SIP", "ALL") -> SIP | C6: =D6&"+"&E6 -> ALARM+ALARMCODE | D6: ALARM | E6: ALARMCODE | F6: 5 | G6: VARCHAR2 | H6: 40 | I6: Y | K6: ALARM이 발생될때 장비등에서 부여하는 Code
A7: =IF(COUNTIFS(컬럼_ISM!$D$2:$D$5176, 컬럼_SIP!D7)=0, "SIP", "ALL") -> SIP | B7: =IF(COUNTIFS(컬럼_ISM!$C$2:$C$5176, 컬럼_SIP!C7)=0, "SIP", "ALL") -> SIP | C7: =D7&"+"&E7 -> ALARM+ALARMTYPE | D7: ALARM | E7: ALARMTYPE | F7: 6 | G7: VARCHAR2 | H7: 40 | I7: Y | K7: ALARM 발생후 사용자가 발생한 Alarm을 handling할수 있는 범위들의 Type(ACTIVATE, ACKNOWLEDGE, CLEAR)
A8: =IF(COUNTIFS(컬럼_ISM!$D$2:$D$5176, 컬럼_SIP!D8)=0, "SIP", "ALL") -> SIP | B8: =IF(COUNTIFS(컬럼_ISM!$C$2:$C$5176, 컬럼_SIP!C8)=0, "SIP", "ALL") -> SIP | C8: =D8&"+"&E8 -> ALARM+DESTTYPE | D8: ALARM | E8: DESTTYPE | F8: 7 | G8: VARCHAR2 | H8: 40 | I8: Y | K8: ALARM 발생시 발생한 ALARM을 알릴수 있는 범위(FAB, Area, Equipment)
A9: =IF(COUNTIFS(컬럼_ISM!$D$2:$D$5176, 컬럼_SIP!D9)=0, "SIP", "ALL") -> SIP | B9: =IF(COUNTIFS(컬럼_ISM!$C$2:$C$5176, 컬럼_SIP!C9)=0, "SIP", "ALL") -> SIP | C9: =D9&"+"&E9 -> ALARM+ALARMTEXT | D9: ALARM | E9: ALARMTEXT | F9: 8 | G9: VARCHAR2 | H9: 1000 | I9: Y | K9: 발생한 ALARM에 대한 상세 내용
A10: =IF(COUNTIFS(컬럼_ISM!$D$2:$D$5176, 컬럼_SIP!D10)=0, "SIP", "ALL") -> SIP | B10: =IF(COUNTIFS(컬럼_ISM!$C$2:$C$5176, 컬럼_SIP!C10)=0, "SIP", "ALL") -> SIP | C10: =D10&"+"&E10 -> ALARM+ALARMSOLVE | D10: ALARM | E10: ALARMSOLVE | F10: 9 | G10: VARCHAR2 | H10: 400 | I10: Y | K10: ALARM 대응방안
A11: =IF(COUNTIFS(컬럼_ISM!$D$2:$D$5176, 컬럼_SIP!D11)=0, "SIP", "ALL") -> SIP | B11: =IF(COUNTIFS(컬럼_ISM!$C$2:$C$5176, 컬럼_SIP!C11)=0, "SIP", "ALL") -> SIP | C11: =D11&"+"&E11 -> ALARM+ALARMSTATE | D11: ALARM | E11: ALARMSTATE | F11: 10 | G11: VARCHAR2 | H11: 40 | I11: Y | K11: 발생한 ALARM의 State (ACTIVATED/ACKNOWLEDGED/CLEARED)
A12: =IF(COUNTIFS(컬럼_ISM!$D$2:$D$5176, 컬럼_SIP!D12)=0, "SIP", "ALL") -> SIP | B12: =IF(COUNTIFS(컬럼_ISM!$C$2:$C$5176, 컬럼_SIP!C12)=0, "SIP", "ALL") -> SIP | C12: =D12&"+"&E12 -> ALARM+AREAID | D12: ALARM | E12: AREAID | F12: 11 | G12: VARCHAR2 | H12: 40 | I12: Y | K12: ALARM이 발생한 AREAID
A13: =IF(COUNTIFS(컬럼_ISM!$D$2:$D$5176, 컬럼_SIP!D13)=0, "SIP", "ALL") -> SIP | B13: =IF(COUNTIFS(컬럼_ISM!$C$2:$C$5176, 컬럼_SIP!C13)=0, "SIP", "ALL") -> SIP | C13: =D13&"+"&E13 -> ALARM+EQUIPMENTID | D13: ALARM | E13: EQUIPMENTID | F13: 12 | G13: VARCHAR2 | H13: 40 | I13: Y | K13: ALARM이 발생된 설비에 부여된 고유한 이름
A14: =IF(COUNTIFS(컬럼_ISM!$D$2:$D$5176, 컬럼_SIP!D14)=0, "SIP", "ALL") -> SIP | B14: =IF(COUNTIFS(컬럼_ISM!$C$2:$C$5176, 컬럼_SIP!C14)=0, "SIP", "ALL") -> SIP | C14: =D14&"+"&E14 -> ALARM+ACKTIME | D14: ALARM | E14: ACKTIME | F14: 13 | G14: DATE | H14: 7 | I14: Y | K14: ALARM State가 Acknowledge일때 시간
A15: =IF(COUNTIFS(컬럼_ISM!$D$2:$D$5176, 컬럼_SIP!D15)=0, "SIP", "ALL") -> SIP | B15: =IF(COUNTIFS(컬럼_ISM!$C$2:$C$5176, 컬럼_SIP!C15)=0, "SIP", "ALL") -> SIP | C15: =D15&"+"&E15 -> ALARM+ACKUSER | D15: ALARM | E15: ACKUSER | F15: 14 | G15: VARCHAR2 | H15: 40 | I15: Y | K15: ALARM State가 Acknowledge로 변경한 User
... A27: =IF(COUNTIFS(컬럼_ISM!$D$2:$D$5176, 컬럼_SIP!D27)=0, "SIP", "ALL") -> SIP | B27: =IF(COUNTIFS(컬럼_ISM!$C$2:$C$5176, 컬럼_SIP!C27)=0, "SIP", "ALL") -> SIP | C27: =D27&"+"&E27 -> ALARM+EVENTCOMMENT | D27: ALARM | E27: EVENTCOMMENT | F27: 26 | G27: VARCHAR2 | H27: 500 | I27: Y | K27: System 커맨트
A28: =IF(COUNTIFS(컬럼_ISM!$D$2:$D$5176, 컬럼_SIP!D28)=0, "SIP", "ALL") -> SIP | B28: =IF(COUNTIFS(컬럼_ISM!$C$2:$C$5176, 컬럼_SIP!C28)=0, "SIP", "ALL") -> SIP | C28: =D28&"+"&E28 -> ALARMACTION+ALARMGROUPID | D28: ALARMACTION | E28: ALARMGROUPID | F28: 1 | G28: VARCHAR2 | H28: 40 | I28: N | J28: PK | K28: ALARM을 발생시키는 곳 (EQP, SPC, SYSTEM)
A29: =IF(COUNTIFS(컬럼_ISM!$D$2:$D$5176, 컬럼_SIP!D29)=0, "SIP", "ALL") -> SIP | B29: =IF(COUNTIFS(컬럼_ISM!$C$2:$C$5176, 컬럼_SIP!C29)=0, "SIP", "ALL") -> SIP | C29: =D29&"+"&E29 -> ALARMACTION+FACTORYID | D29: ALARMACTION | E29: FACTORYID | F29: 2 | G29: VARCHAR2 | H29: 40 | I29: N | J29: PK | K29: 공장 ID
A30: =IF(COUNTIFS(컬럼_ISM!$D$2:$D$5176, 컬럼_SIP!D30)=0, "SIP", "ALL") -> SIP | B30: =IF(COUNTIFS(컬럼_ISM!$C$2:$C$5176, 컬럼_SIP!C30)=0, "SIP", "ALL") -> SIP | C30: =D30&"+"&E30 -> ALARMACTION+ALARMLEVEL | D30: ALARMACTION | E30: ALARMLEVEL | F30: 3 | G30: VARCHAR2 | H30: 40 | I30: N | J30: PK | K30: ALARM 등급에 대한 Level(INFO, WARNING, ALARM)
A31: =IF(COUNTIFS(컬럼_ISM!$D$2:$D$5176, 컬럼_SIP!D31)=0, "SIP", "ALL") -> SIP | B31: =IF(COUNTIFS(컬럼_ISM!$C$2:$C$5176, 컬럼_SIP!C31)=0, "SIP", "ALL") -> SIP | C31: =D31&"+"&E31 -> ALARMACTION+ALARMTYPE | D31: ALARMACTION | E31: ALARMTYPE | F31: 4 | G31: VARCHAR2 | H31: 40 | I31: N | J31: PK | K31: ALARM 발생후 사용자가 발생한 Alarm을 handling할수 있는 범위들의 Type(ACTIVATE, ACKNOWLEDGE, CLEAR)
A32: =IF(COUNTIFS(컬럼_ISM!$D$2:$D$5176, 컬럼_SIP!D32)=0, "SIP", "ALL") -> SIP | B32: =IF(COUNTIFS(컬럼_ISM!$C$2:$C$5176, 컬럼_SIP!C32)=0, "SIP", "ALL") -> SIP | C32: =D32&"+"&E32 -> ALARMACTION+ACTION | D32: ALARMACTION | E32: ACTION | F32: 5 | G32: VARCHAR2 | H32: 40 | I32: N | J32: PK | K32: ALARM 발생시 알람행위(HoldLot,HoldEQP,Email,SMS,AlarmLamp)
A33: =IF(COUNTIFS(컬럼_ISM!$D$2:$D$5176, 컬럼_SIP!D33)=0, "SIP", "ALL") -> SIP | B33: =IF(COUNTIFS(컬럼_ISM!$C$2:$C$5176, 컬럼_SIP!C33)=0, "SIP", "ALL") -> SIP | C33: =D33&"+"&E33 -> ALARMACTION+CHECKOUTSTATE | D33: ALARMACTION | E33: CHECKOUTSTATE | F33: 6 | G33: VARCHAR2 | H33: 40 | I33: Y | K33: User별 데이터 편집상태 (CheckedIn/CheckedOut/CancelCheckedOut)
A34: =IF(COUNTIFS(컬럼_ISM!$D$2:$D$5176, 컬럼_SIP!D34)=0, "SIP", "ALL") -> SIP | B34: =IF(COUNTIFS(컬럼_ISM!$C$2:$C$5176, 컬럼_SIP!C34)=0, "SIP", "ALL") -> SIP | C34: =D34&"+"&E34 -> ALARMACTION+CHECKOUTTIME | D34: ALARMACTION | E34: CHECKOUTTIME | F34: 7 | G34: DATE | H34: 7 | I34: Y | K34: 데이터 편집위해 CheckOut시간
A35: =IF(COUNTIFS(컬럼_ISM!$D$2:$D$5176, 컬럼_SIP!D35)=0, "SIP", "ALL") -> SIP | B35: =IF(COUNTIFS(컬럼_ISM!$C$2:$C$5176, 컬럼_SIP!C35)=0, "SIP", "ALL") -> SIP | C35: =D35&"+"&E35 -> ALARMACTION+CHECKOUTUSER | D35: ALARMACTION | E35: CHECKOUTUSER | F35: 8 | G35: VARCHAR2 | H35: 40 | I35: Y | K35: CheckOut 사용자ID
A36: =IF(COUNTIFS(컬럼_ISM!$D$2:$D$5176, 컬럼_SIP!D36)=0, "SIP", "ALL") -> SIP | B36: =IF(COUNTIFS(컬럼_ISM!$C$2:$C$5176, 컬럼_SIP!C36)=0, "SIP", "ALL") -> SIP | C36: =D36&"+"&E36 -> ALARMACTION+DATASTATE | D36: ALARMACTION | E36: DATASTATE | F36: 9 | G36: VARCHAR2 | H36: 10 | I36: Y | K36: 변경 상태 (Created/Removed)
A37: =IF(COUNTIFS(컬럼_ISM!$D$2:$D$5176, 컬럼_SIP!D37)=0, "SIP", "ALL") -> SIP | B37: =IF(COUNTIFS(컬럼_ISM!$C$2:$C$5176, 컬럼_SIP!C37)=0, "SIP", "ALL") -> SIP | C37: =D37&"+"&E37 -> ALARMACTION+EVENT | D37: ALARMACTION | E37: EVENT | F37: 10 | G37: VARCHAR2 | H37: 40 | I37: Y | K37: 이벤트 (CheckedIn/CheckedOut/CancelCheckedOut/Created/Modify/Removed)
A38: =IF(COUNTIFS(컬럼_ISM!$D$2:$D$5176, 컬럼_SIP!D38)=0, "SIP", "ALL") -> SIP | B38: =IF(COUNTIFS(컬럼_ISM!$C$2:$C$5176, 컬럼_SIP!C38)=0, "SIP", "ALL") -> SIP | C38: =D38&"+"&E38 -> ALARMACTION+TIMEKEY | D38: ALARMACTION | E38: TIMEKEY | F38: 11 | G38: VARCHAR2 | H38: 40 | I38: Y | K38: 이벤트 발생 Key
A39: =IF(COUNTIFS(컬럼_ISM!$D$2:$D$5176, 컬럼_SIP!D39)=0, "SIP", "ALL") -> SIP | B39: =IF(COUNTIFS(컬럼_ISM!$C$2:$C$5176, 컬럼_SIP!C39)=0, "SIP", "ALL") -> SIP | C39: =D39&"+"&E39 -> ALARMACTION+EVENTTIME | D39: ALARMACTION | E39: EVENTTIME | F39: 12 | G39: DATE | H39: 7 | I39: Y | K39: 이벤트 발생 시간
A40: =IF(COUNTIFS(컬럼_ISM!$D$2:$D$5176, 컬럼_SIP!D40)=0, "SIP", "ALL") -> SIP | B40: =IF(COUNTIFS(컬럼_ISM!$C$2:$C$5176, 컬럼_SIP!C40)=0, "SIP", "ALL") -> SIP | C40: =D40&"+"&E40 -> ALARMACTION+EVENTUSER | D40: ALARMACTION | E40: EVENTUSER | F40: 13 | G40: VARCHAR2 | H40: 40 | I40: Y | K40: 이벤트 발생 사용자
A41: =IF(COUNTIFS(컬럼_ISM!$D$2:$D$5176, 컬럼_SIP!D41)=0, "SIP", "ALL") -> SIP | B41: =IF(COUNTIFS(컬럼_ISM!$C$2:$C$5176, 컬럼_SIP!C41)=0, "SIP", "ALL") -> SIP | C41: =D41&"+"&E41 -> ALARMACTION+EVENTCOMMENT | D41: ALARMACTION | E41: EVENTCOMMENT | F41: 14 | G41: VARCHAR2 | H41: 500 | I41: Y | K41: System 커맨트
A42: =IF(COUNTIFS(컬럼_ISM!$D$2:$D$5176, 컬럼_SIP!D42)=0, "SIP", "ALL") -> SIP | B42: =IF(COUNTIFS(컬럼_ISM!$C$2:$C$5176, 컬럼_SIP!C42)=0, "SIP", "ALL") -> SIP | C42: =D42&"+"&E42 -> ALARMACTIONHISTORY+ALARMGROUPID | D42: ALARMACTIONHISTORY | E42: ALARMGROUPID | F42: 1 | G42: VARCHAR2 | H42: 40 | I42: N | J42: PK | K42: ALARM을 발생시키는 곳 (EQP, SPC, SYSTEM)
A43: =IF(COUNTIFS(컬럼_ISM!$D$2:$D$5176, 컬럼_SIP!D43)=0, "SIP", "ALL") -> SIP | B43: =IF(COUNTIFS(컬럼_ISM!$C$2:$C$5176, 컬럼_SIP!C43)=0, "SIP", "ALL") -> SIP | C43: =D43&"+"&E43 -> ALARMACTIONHISTORY+FACTORYID | D43: ALARMACTIONHISTORY | E43: FACTORYID | F43: 2 | G43: VARCHAR2 | H43: 40 | I43: N | J43: PK | K43: 공장 ID
A44: =IF(COUNTIFS(컬럼_ISM!$D$2:$D$5176, 컬럼_SIP!D44)=0, "SIP", "ALL") -> SIP | B44: =IF(COUNTIFS(컬럼_ISM!$C$2:$C$5176, 컬럼_SIP!C44)=0, "SIP", "ALL") -> SIP | C44: =D44&"+"&E44 -> ALARMACTIONHISTORY+ALARMLEVEL | D44: ALARMACTIONHISTORY | E44: ALARMLEVEL | F44: 3 | G44: VARCHAR2 | H44: 40 | I44: N | J44: PK | K44: ALARM 등급에 대한 Level(INFO, WARNING, ALARM)
A45: =IF(COUNTIFS(컬럼_ISM!$D$2:$D$5176, 컬럼_SIP!D45)=0, "SIP", "ALL") -> SIP | B45: =IF(COUNTIFS(컬럼_ISM!$C$2:$C$5176, 컬럼_SIP!C45)=0, "SIP", "ALL") -> SIP | C45: =D45&"+"&E45 -> ALARMACTIONHISTORY+ALARMTYPE | D45: ALARMACTIONHISTORY | E45: ALARMTYPE | F45: 4 | G45: VARCHAR2 | H45: 40 | I45: N | J45: PK | K45: ALARM 발생후 사용자가 발생한 Alarm을 handling할수 있는 범위들의 Type(ACTIVATE, ACKNOWLEDGE, CLEAR)
A46: =IF(COUNTIFS(컬럼_ISM!$D$2:$D$5176, 컬럼_SIP!D46)=0, "SIP", "ALL") -> SIP | B46: =IF(COUNTIFS(컬럼_ISM!$C$2:$C$5176, 컬럼_SIP!C46)=0, "SIP", "ALL") -> SIP | C46: =D46&"+"&E46 -> ALARMACTIONHISTORY+ACTION | D46: ALARMACTIONHISTORY | E46: ACTION | F46: 5 | G46: VARCHAR2 | H46: 40 | I46: N | J46: PK | K46: ALARM 발생시 알람행위(HoldLot,HoldEQP,Email,SMS,AlarmLamp)
A47: =IF(COUNTIFS(컬럼_ISM!$D$2:$D$5176, 컬럼_SIP!D47)=0, "SIP", "ALL") -> SIP | B47: =IF(COUNTIFS(컬럼_ISM!$C$2:$C$5176, 컬럼_SIP!C47)=0, "SIP", "ALL") -> SIP | C47: =D47&"+"&E47 -> ALARMACTIONHISTORY+CHECKOUTSTATE | D47: ALARMACTIONHISTORY | E47: CHECKOUTSTATE | F47: 6 | G47: VARCHAR2 | H47: 40 | I47: Y | K47: User별 데이터 편집상태 (CheckedIn/CheckedOut/CancelCheckedOut)
A48: =IF(COUNTIFS(컬럼_ISM!$D$2:$D$5176, 컬럼_SIP!D48)=0, "SIP", "ALL") -> SIP | B48: =IF(COUNTIFS(컬럼_ISM!$C$2:$C$5176, 컬럼_SIP!C48)=0, "SIP", "ALL") -> SIP | C48: =D48&"+"&E48 -> ALARMACTIONHISTORY+CHECKOUTTIME | D48: ALARMACTIONHISTORY | E48: CHECKOUTTIME | F48: 7 | G48: DATE | H48: 7 | I48: Y | K48: 데이터 편집위해 CheckOut시간
A49: =IF(COUNTIFS(컬럼_ISM!$D$2:$D$5176, 컬럼_SIP!D49)=0, "SIP", "ALL") -> SIP | B49: =IF(COUNTIFS(컬럼_ISM!$C$2:$C$5176, 컬럼_SIP!C49)=0, "SIP", "ALL") -> SIP | C49: =D49&"+"&E49 -> ALARMACTIONHISTORY+CHECKOUTUSER | D49: ALARMACTIONHISTORY | E49: CHECKOUTUSER | F49: 8 | G49: VARCHAR2 | H49: 40 | I49: Y | K49: CheckOut 사용자ID
A50: =IF(COUNTIFS(컬럼_ISM!$D$2:$D$5176, 컬럼_SIP!D50)=0, "SIP", "ALL") -> SIP | B50: =IF(COUNTIFS(컬럼_ISM!$C$2:$C$5176, 컬럼_SIP!C50)=0, "SIP", "ALL") -> SIP | C50: =D50&"+"&E50 -> ALARMACTIONHISTORY+DATASTATE | D50: ALARMACTIONHISTORY | E50: DATASTATE | F50: 9 | G50: VARCHAR2 | H50: 10 | I50: Y | K50: 변경 상태 (Created/Removed)
A51: =IF(COUNTIFS(컬럼_ISM!$D$2:$D$5176, 컬럼_SIP!D51)=0, "SIP", "ALL") -> SIP | B51: =IF(COUNTIFS(컬럼_ISM!$C$2:$C$5176, 컬럼_SIP!C51)=0, "SIP", "ALL") -> SIP | C51: =D51&"+"&E51 -> ALARMACTIONHISTORY+EVENT | D51: ALARMACTIONHISTORY | E51: EVENT | F51: 10 | G51: VARCHAR2 | H51: 40 | I51: Y | K51: 이벤트 (CheckedIn/CheckedOut/CancelCheckedOut/Created/Modify/Removed)
...

Sheet 데이터 추출 쿼리
A1: MES Table 기준 정보추출. | B1: MES COLUMN 기준 정보추출.
A2: SELECT T.TABLE_NAME, C.COMMENTS, CASE WHEN INSTR(T.TABLESPACE_NAME, 'HIST') > 0 THEN 'History' ELSE 'Master' END AS CURHIST, T.TABLESPACE_NAME AS TABLESPACE_TABLE, I.TABLESPACE_NAME AS TABLESPACE_INDEX, DECODE(P.PARTITION_NAME, NULL, '', P.PARTITION_NAME) PARTITION_BY FROM USER_TABLES T JOIN USER_TAB_COMMENTS C ON T.TABLE_NAME = C.TABLE_NAME LEFT JOIN ( SELECT TABLE_NAME, MAX(INDEX_NAME), MAX(TABLESPACE_NAME) TABLESPACE_NAME FROM USER_INDEXES GROUP BY TABLE_NAME ) I ON T.TABLE_NAME = I.TABLE_NAME LEFT JOIN ( SELECT TABLE_NAME, MAX(PARTITION_NAME) PARTITION_NAME FROM USER_TAB_PARTITIONS GROUP BY TABLE_NAME ) P ON T.TABLE_NAME = P.TABLE_NAME ORDER BY T.TABLE_NAME ; | B2: SELECT C.TABLE_NAME AS TAB_NAME, C.COLUMN_NAME AS COL_NAME, C.COLUMN_ID AS COL_ID, C.DATA_TYPE AS TYPE, C.DATA_LENGTH AS LENGTH, C.NULLABLE, DECODE(P.COLUMN_NAME, NULL, '', 'PK') AS PK, CM.COMMENTS FROM USER_TAB_COLUMNS C LEFT JOIN USER_COL_COMMENTS CM ON C.TABLE_NAME = CM.TABLE_NAME AND C.COLUMN_NAME = CM.COLUMN_NAME LEFT JOIN ( SELECT ACC.TABLE_NAME, ACC.COLUMN_NAME FROM USER_CONSTRAINTS AC JOIN USER_CONS_COLUMNS ACC ON AC.CONSTRAINT_NAME = ACC.CONSTRAINT_NAME WHERE AC.CONSTRAINT_TYPE = 'P' ) P ON C.TABLE_NAME = P.TABLE_NAME AND C.COLUMN_NAME = P.COLUMN_NAME ORDER BY C.TABLE_NAME, C.COLUMN_ID ;
